<mujoco model="pupper_v3_2">
    <!-- TODO: Why can't I specify defaults here? -->
    <!-- <compiler angle="radian" meshdir="assets" autolimits="true" /> -->
    <!-- <default>
        <motor forcelimited="true" forcerange="-3 3" ctrlrange="-3 3" ctrllimited="true" />
        <geom condim="1" friction="1.0" solimp=".9 .99 .003" solref=".015 1" />
        <joint armature="0.0016" type="hinge" damping="0.0001" frictionloss="0.01" limited="true"
            solimplimit="0 .99 .01" />
    </default> -->
    <body name="leg_front_r_1" pos="0.075 -0.05 0" quat="0.707105 0.707108 0 0" gravcomp="0">
        <inertial pos="0.00272 -1e-05 0.03409" mass="0.2" diaginertia="0.0002 0.0002 0.0002" />
        <joint name="leg_front_r_1" pos="0 0 0" axis="0 0 1" range="-1.22173 2.0944" />
        <!-- <geom size="0.0265 0.0125" pos="0 0 0.034" quat="0.707105 0 -0.707108 0"
        type="cylinder"
            rgba="0.70196 0.70196 0.70196 1" /> -->
        <geom size="0.0125 0.0265 0.0265" pos="0. 0 0.034" quat="0.707105 0.707108 0 0"
            type="box" rgba="0.7 0.7 0.7 0.2" />
        <body name="leg_front_r_2" pos="0 0 0.034" quat="0.499998 -0.5 -0.500002 0.5" gravcomp="0">
            <inertial pos="-0.04555 -0.00233 0.05745" mass="0.2" diaginertia="0.0002 0.0002 0.0002" />
            <joint name="leg_front_r_2" pos="0 0 0" axis="0 0 1" range="-0.5236 0.87266" />
            <geom size="0.03989 0.015615 0.01448" pos="-0.01721 1e-05 0.04981"
                quat="0.906309 0 0.422616 0" type="box" rgba="0.70196 0.70196 0.70196 1" />
            <!-- <geom size="0.0265 0.0125" pos="-0.0515 0 0.07" quat="0.499998 0.5 0.5 -0.500002"
                type="cylinder" rgba="0.70196 0.70196 0.70196 1" /> -->
            <body name="leg_front_r_3" pos="-0.0515 0 0.07"
                quat="0.298835 0.298836 0.640855 -0.640858"
                gravcomp="0">
                <inertial pos="0.08114 -0.0073 0.01746" mass="0.045"
                    diaginertia="0.0001 0.0001 0.0001" />
                <joint name="leg_front_r_3" pos="0 0 0" axis="0 0 1" range="-3.05433 0.82903" />
                <geom size="0.03483 0.007915 0.00724" pos="0.04385 -0.0046 0.01846"
                    quat="0.706109 -0.706112 -0.0375192 0.0375191" type="box"
                    rgba="0.96471 0.96471 0.95294 1" />
                <geom size="0.01984" pos="0.08746 -0.0107 0.0189" rgba="0.96471 0.96471 0.95294 1" />
            </body>
        </body>
    </body>

    <body name="leg_front_l_1" pos="0.075 0.05 0" quat="0.707105 -0.707108 0 0" gravcomp="0">
        <inertial pos="0.00263 8e-05 0.03455" mass="0.2" diaginertia="0.0002 0.0002 0.0002" />
        <joint name="leg_front_l_1" pos="0 0 0" axis="0 0 1" range="-2.0944 1.22173" />
        <geom size="0.0125 0.0265 0.0265" pos="0. 0 0.034" quat="0.707105 0.707108 0 0"
            type="box" rgba="0.7 0.7 0.7 0.2" />
        <!-- <geom size="0.0265 0.0125" pos="0 0 0.034" quat="9.38184e-07 -0.707105 9.38187e-07
        0.707108"
            type="cylinder" rgba="0.70196 0.70196 0.70196 1" /> -->
        <body name="leg_front_l_2" pos="0 0 0.034" quat="0.499998 0.5 0.500002 0.5" gravcomp="0">
            <inertial pos="0.0461 0.00255 -0.05754" mass="0.2" diaginertia="0.0002 0.0002 0.0002" />
            <joint name="leg_front_l_2" pos="0 0 0" axis="0 0 -1" range="-0.87266 0.5236" />
            <geom size="0.03989 0.015615 0.01448" pos="0.01721 -1e-05 -0.04981"
                quat="0.422617 0 -0.906308 0" type="box" rgba="0.62745 0.62745 0.62745 1" />
            <!-- <geom size="0.0265 0.0125" pos="0.0515 0 -0.07" quat="0.499998 0.5 -0.5 0.500002"
                type="cylinder" rgba="0.62745 0.62745 0.62745 1" /> -->
            <body name="leg_front_l_3" pos="0.0515 0 -0.07"
                quat="0.298835 0.298836 0.640855 -0.640858"
                gravcomp="0">
                <inertial pos="-0.08114 0.0073 -0.01746" mass="0.045"
                    diaginertia="0.0001 0.0001 0.0001" />
                <joint name="leg_front_l_3" pos="0 0 0" axis="0 0 -1" range="-0.82903 3.05433" />
                <geom size="0.03483 0.007915 0.00724" pos="-0.04385 0.0046 -0.01846"
                    quat="0.03752 -0.0375201 0.706112 -0.706109" type="box" rgba="0 0 0 1" />
                <geom size="0.01984" pos="-0.08746 0.0107 -0.0189" quat="1.32679e-06 0 1 0"
                    rgba="0 0 0 1" />
            </body>
        </body>
    </body>

    <body name="leg_back_r_1" pos="-0.075 -0.05 0" quat="0.707105 0.707108 0 0" gravcomp="0">
        <inertial pos="0.00272 -1e-05 0.03409" mass="0.2" diaginertia="0.0002 0.0002 0.0002" />
        <joint name="leg_back_r_1" pos="0 0 0" axis="0 0 1" range="-1.22173 2.0944" />
        <geom size="0.0125 0.0265 0.0265" pos="0. 0 0.034" quat="0.707105 0.707108 0 0"
            type="box" rgba="0.7 0.7 0.7 0.2" />
        <!-- <geom size="0.0265 0.0125" pos="0 0 0.034" quat="0.707105 0 -0.707108 0"
        type="cylinder"
            rgba="0.70196 0.70196 0.70196 1" /> -->
        <body name="leg_back_r_2" pos="0 0 0.034" quat="0.499998 -0.5 -0.500002 0.5" gravcomp="0">
            <inertial pos="-0.04555 -0.00233 0.05745" mass="0.2" diaginertia="0.0002 0.0002 0.0002" />
            <joint name="leg_back_r_2" pos="0 0 0" axis="0 0 1" range="-0.5236 0.87266" />
            <geom size="0.03989 0.015615 0.01448" pos="-0.01721 1e-05 0.04981"
                quat="0.906309 0 0.422616 0" type="box" rgba="0.70196 0.70196 0.70196 1" />
            <!-- <geom size="0.0265 0.0125" pos="-0.0515 0 0.07" quat="0.499998 0.5 0.5 -0.500002"
                type="cylinder" rgba="0.70196 0.70196 0.70196 1" /> -->
            <body name="leg_back_r_3" pos="-0.0515 0 0.07"
                quat="0.298835 0.298836 0.640855 -0.640858"
                gravcomp="0">
                <inertial pos="0.08114 -0.0073 0.01746" mass="0.045"
                    diaginertia="0.0001 0.0001 0.0001" />
                <joint name="leg_back_r_3" pos="0 0 0" axis="0 0 1" range="-3.05433 0.82903" />
                <geom size="0.03483 0.007915 0.00724" pos="0.04385 -0.0046 0.01846"
                    quat="0.706109 -0.706112 -0.0375192 0.0375191" type="box"
                    rgba="0.62745 0.83922 1 1" />
                <geom size="0.01984" pos="0.08746 -0.0107 0.0189" rgba="0.62745 0.83922 1 1" />
            </body>
        </body>
    </body>

    <body name="leg_back_l_1" pos="-0.075 0.05 0" quat="0.707105 -0.707108 0 0" gravcomp="0">
        <inertial pos="0.00263 8e-05 0.03455" mass="0.2" diaginertia="0.0002 0.0002 0.0002" />
        <joint name="leg_back_l_1" pos="0 0 0" axis="0 0 1" range="-2.0944 1.22173" />
        <geom size="0.0125 0.0265 0.0265" pos="0. 0 0.034" quat="0.707105 0.707108 0 0"
            type="box" rgba="0.7 0.7 0.7 0.2" />
        <!-- <geom size="0.0265 0.0125" pos="0 0 0.034" quat="9.38184e-07 -0.707105 9.38187e-07
        0.707108"
            type="cylinder" rgba="0.70196 0.70196 0.70196 1" /> -->
        <body name="leg_back_l_2" pos="0 0 0.034" quat="0.499998 0.5 0.500002 0.5" gravcomp="0">
            <inertial pos="0.0461 0.00255 -0.05754" mass="0.2" diaginertia="0.0002 0.0002 0.0002" />
            <joint name="leg_back_l_2" pos="0 0 0" axis="0 0 -1" range="-0.87266 0.5236" />
            <geom size="0.03989 0.015615 0.01448" pos="0.01721 -1e-05 -0.04981"
                quat="0.422617 0 -0.906308 0" type="box" rgba="0.70196 0.70196 0.70196 1" />
            <!-- <geom size="0.0265 0.0125" pos="0.0515 0 -0.07" quat="0.499998 0.5 -0.5 0.500002"
                type="cylinder" rgba="0.70196 0.70196 0.70196 1" /> -->
            <body name="leg_back_l_3" pos="0.0515 0 -0.07"
                quat="0.298835 0.298836 0.640855 -0.640858"
                gravcomp="0">
                <inertial pos="-0.08114 0.0073 -0.01746" mass="0.045"
                    diaginertia="0.0001 0.0001 0.0001" />
                <joint name="leg_back_l_3" pos="0 0 0" axis="0 0 -1" range="-0.82903 3.05433" />
                <geom size="0.03483 0.007915 0.00724" pos="-0.04385 0.0046 -0.01846"
                    quat="0.03752 -0.0375201 0.706112 -0.706109" type="box"
                    rgba="0.62745 0.83922 1 1" />
                <geom size="0.01984" pos="-0.08746 0.0107 -0.0189" quat="1.32679e-06 0 1 0"
                    rgba="0.62745 0.83922 1 1" />
            </body>
        </body>
    </body>
    <site name="torso_imu_site" pos="0.09 0 0.032" />
</mujoco>